Workbook

Sheet chatGPT3.5
A2: chatGPT3.5
A3: Input USD / 1M | B3: =Model_Prices!$C$6 -> 0.5 | D3: API model | E3: gpt-3.5-turbo | G3: Price checked | H3: 2026-09-09
A4: Encoding | B4: cl100k_base | D4: tiktoken | E4: 0.14.0 | G4: Seed / max samples | H4: 42 / 10000
A6: H = actual history steps. Upstream H = H-1. Input only; standard uncached rates; +9 framing is an estimate.
A8: タスク | B8: 100回分金額 | C8: H=10 合計金額 平均（USD） | D8: H=10 合計金額 平均＋履歴標準偏差（USD） | E8: 固定部分＋質問 平均トークン数 | F8: H=1 履歴 平均トークン数 | G8: H=1 履歴 標準偏差（トークン） | H8: H=10 履歴 平均トークン数 | I8: H=10 合計 平均トークン数 | J8: H=10 履歴 平均＋標準偏差（トークン） | K8: H=10 合計 平均＋履歴標準偏差（トークン） | L8: H=10 履歴 標準偏差（トークン） | M8: H=10 プロンプト全体 平均トークン数 | N8: H=10 分割集計－全体集計 平均差（トークン） | O8: 計測状況
A9: Acrobot-v1 | B9: =C9*100 -> 0.067701003 | C9: =I9/1000000*Model_Prices!$C$6 -> 0.00067701003 | D9: =K9/1000000*Model_Prices!$C$6 -> 0.00068025722 | E9: 771.27221 | F9: 58.284264 | G9: 1.9924747 | H9: 582.74785 | I9: =E9+H9 -> 1354.0201 | J9: =H9+L9 -> 589.24224 | K9: =E9+J9 -> 1360.5144 | L9: 6.4943905 | M9: 1354.0201 | N9: =ROUND(I9-M9,9) -> 0 | O9: ok
A10: MountainCar-v0 | B10: =C10*100 -> 0.045123486 | C10: =I10/1000000*Model_Prices!$C$6 -> 0.00045123486 | D10: =K10/1000000*Model_Prices!$C$6 -> 0.00045488656 | E10: 581.14346 | F10: 32.086324 | G10: 1.0981499 | H10: 321.32625 | I10: =E10+H10 -> 902.46971 | J10: =H10+L10 -> 328.62967 | K10: =E10+J10 -> 909.77313 | L10: 7.3034167 | M10: 902.46971 | N10: =ROUND(I10-M10,9) -> 0 | O10: ok
A11: Pendulum-v1 | B11: =C11*100 -> 0.073394789 | C11: =I11/1000000*Model_Prices!$C$6 -> 0.00073394789 | D11: =K11/1000000*Model_Prices!$C$6 -> 0.00073629586 | E11: 1023.4711 | F11: 44.422613 | G11: 1.443332 | H11: 444.42474 | I11: =E11+H11 -> 1467.8958 | J11: =H11+L11 -> 449.12066 | K11: =E11+J11 -> 1472.5917 | L11: 4.6959242 | M11: 1467.8958 | N11: =ROUND(I11-M11,9) -> 0 | O11: ok
A12: BipedalWalker-v3 | B12: n.a. | C12: n.a. | D12: n.a. | E12: n.a. | F12: n.a. | G12: n.a. | H12: n.a. | I12: n.a. | J12: n.a. | K12: n.a. | L12: n.a. | M12: n.a. | N12: n.a. | O12: UNSUPPORTED_TASK: Original LLM-X task class/description is unavailable; raw inspection only.
A13: CartPole-v1 | B13: =C13*100 -> 0.059847204 | C13: =I13/1000000*Model_Prices!$C$6 -> 0.00059847204 | D13: =K13/1000000*Model_Prices!$C$6 -> 0.00060117444 | E13: 745.26857 | F13: 45.168337 | G13: 1.4070106 | H13: 451.67551 | I13: =E13+H13 -> 1196.9441 | J13: =H13+L13 -> 457.08031 | K13: =E13+J13 -> 1202.3489 | L13: 5.4047987 | M13: 1196.9441 | N13: =ROUND(I13-M13,9) -> 0 | O13: ok
A14: FetchPickAndPlace-v2 | B14: =C14*100 -> 0.249966 | C14: =I14/1000000*Model_Prices!$C$6 -> 0.00249966 | D14: =K14/1000000*Model_Prices!$C$6 -> 0.0025113621 | E14: 2161.06 | F14: 283.51429 | G14: 7.4937253 | H14: 2838.26 | I14: =E14+H14 -> 4999.32 | J14: =H14+L14 -> 2861.6642 | K14: =E14+J14 -> 5022.7242 | L14: 23.404218 | M14: 4999.32 | N14: =ROUND(I14-M14,9) -> 0 | O14: ok
A15: FetchPush-v2 | B15: =C15*100 -> 0.24976387 | C15: =I15/1000000*Model_Prices!$C$6 -> 0.0024976387 | D15: =K15/1000000*Model_Prices!$C$6 -> 0.0025068418 | E15: 2138.1075 | F15: 285.72653 | G15: 4.2420045 | H15: 2857.17 | I15: =E15+H15 -> 4995.2775 | J15: =H15+L15 -> 2875.576 | K15: =E15+J15 -> 5013.6835 | L15: 18.406007 | M15: 4995.2775 | N15: =ROUND(I15-M15,9) -> 0 | O15: ok
A16: FetchSlide-v2 | B16: =C16*100 -> 0.25145475 | C16: =I16/1000000*Model_Prices!$C$6 -> 0.0025145475 | D16: =K16/1000000*Model_Prices!$C$6 -> 0.0025253284 | E16: 2178.5825 | F16: 284.97143 | G16: 6.5211743 | H16: 2850.5125 | I16: =E16+H16 -> 5029.095 | J16: =H16+L16 -> 2872.0744 | K16: =E16+J16 -> 5050.6569 | L16: 21.561884 | M16: 5029.095 | N16: =ROUND(I16-M16,9) -> 0 | O16: ok
A17: HalfCheetah-v4 | B17: n.a. | C17: n.a. | D17: n.a. | E17: n.a. | F17: n.a. | G17: n.a. | H17: n.a. | I17: n.a. | J17: n.a. | K17: n.a. | L17: n.a. | M17: n.a. | N17: n.a. | O17: UNSUPPORTED_TASK: Original LLM-X task class/description is unavailable; raw inspection only.
A18: InvertedDoublePendulum-v4 | B18: =C18*100 -> 0.1158879 | C18: =I18/1000000*Model_Prices!$C$6 -> 0.001158879 | D18: =K18/1000000*Model_Prices!$C$6 -> 0.0011664988 | E18: 1360.3516 | F18: 95.808712 | G18: 4.9012367 | H18: 957.40639 | I18: =E18+H18 -> 2317.758 | J18: =H18+L18 -> 972.64601 | K18: =E18+J18 -> 2332.9976 | L18: 15.239613 | M18: 2317.758 | N18: =ROUND(I18-M18,9) -> 0 | O18: ok
A19: InvertedPendulum-v4 | B19: =C19*100 -> 0.071490935 | C19: =I19/1000000*Model_Prices!$C$6 -> 0.00071490935 | D19: =K19/1000000*Model_Prices!$C$6 -> 0.0007172108 | E19: 944.26178 | F19: 48.595474 | G19: 1.4243317 | H19: 485.55693 | I19: =E19+H19 -> 1429.8187 | J19: =H19+L19 -> 490.15981 | K19: =E19+J19 -> 1434.4216 | L19: 4.6028872 | M19: 1429.8187 | N19: =ROUND(I19-M19,9) -> 0 | O19: ok
A20: LunarLander-v2 | B20: =C20*100 -> 0.086072269 | C20: =I20/1000000*Model_Prices!$C$6 -> 0.00086072269 | D20: =K20/1000000*Model_Prices!$C$6 -> 0.00089881481 | E20: 956.93277 | F20: 76.921727 | G20: 9.110912 | H20: 764.51261 | I20: =E20+H20 -> 1721.4454 | J20: =H20+L20 -> 840.69685 | K20: =E20+J20 -> 1797.6296 | L20: 76.184249 | M20: 1721.4454 | N20: =ROUND(I20-M20,9) -> 0 | O20: ok
A21: MiniGrid-DoorKey-5x5-v0 | B21: n.a. | C21: n.a. | D21: n.a. | E21: n.a. | F21: n.a. | G21: n.a. | H21: n.a. | I21: n.a. | J21: n.a. | K21: n.a. | L21: n.a. | M21: n.a. | N21: n.a. | O21: UNSUPPORTED_TASK: Original LLM-X task class/description is unavailable; raw inspection only.
A22: MiniGrid-Empty-Random-5x5-v0 | B22: n.a. | C22: n.a. | D22: n.a. | E22: n.a. | F22: n.a. | G22: n.a. | H22: n.a. | I22: n.a. | J22: n.a. | K22: n.a. | L22: n.a. | M22: n.a. | N22: n.a. | O22: UNSUPPORTED_TASK: Original LLM-X task class/description is unavailable; raw inspection only.
A23: MiniGrid-Fetch-5x5-N2-v0 | B23: n.a. | C23: n.a. | D23: n.a. | E23: n.a. | F23: n.a. | G23: n.a. | H23: n.a. | I23: n.a. | J23: n.a. | K23: n.a. | L23: n.a. | M23: n.a. | N23: n.a. | O23: UNSUPPORTED_TASK: Original LLM-X task class/description is unavailable; raw inspection only.
A24: MiniGrid-GoToDoor-5x5-v0 | B24: n.a. | C24: n.a. | D24: n.a. | E24: n.a. | F24: n.a. | G24: n.a. | H24: n.a. | I24: n.a. | J24: n.a. | K24: n.a. | L24: n.a. | M24: n.a. | N24: n.a. | O24: UNSUPPORTED_TASK: Original LLM-X task class/description is unavailable; raw inspection only.
A25: MiniGrid-KeyCorridorS3R1-v0 | B25: n.a. | C25: n.a. | D25: n.a. | E25: n.a. | F25: n.a. | G25: n.a. | H25: n.a. | I25: n.a. | J25: n.a. | K25: n.a. | L25: n.a. | M25: n.a. | N25: n.a. | O25: UNSUPPORTED_TASK: Original LLM-X task class/description is unavailable; raw inspection only.
A26: MiniGrid-Unlock-v0 | B26: =C26*100 -> 0.31105 | C26: =I26/1000000*Model_Prices!$C$6 -> 0.0031105 | D26: =K26/1000000*Model_Prices!$C$6 -> 0.0031105 | E26: 1131 | F26: 509 | G26: 0 | H26: 5090 | I26: =E26+H26 -> 6221 | J26: =H26+L26 -> 5090 | K26: =E26+J26 -> 6221 | L26: 0 | M26: 6221 | N26: =ROUND(I26-M26,9) -> 0 | O26: ok
A27: Pusher-v4 | B27: n.a. | C27: n.a. | D27: n.a. | E27: n.a. | F27: n.a. | G27: n.a. | H27: n.a. | I27: n.a. | J27: n.a. | K27: n.a. | L27: n.a. | M27: n.a. | N27: n.a. | O27: UNSUPPORTED_TASK: Original LLM-X task class/description is unavailable; raw inspection only.
A28: Reacher-v4 | B28: n.a. | C28: n.a. | D28: n.a. | E28: n.a. | F28: n.a. | G28: n.a. | H28: n.a. | I28: n.a. | J28: n.a. | K28: n.a. | L28: n.a. | M28: n.a. | N28: n.a. | O28: UNSUPPORTED_TASK: Original LLM-X task class/description is unavailable; raw inspection only.
A32: タスク | B32: 実際の履歴長H （ステップ） | C32: 公式関数へ渡すH | D32: 有効ウィンドウ数 | E32: 抽出ウィンドウ数 | F32: 抽出対象エピソード数 | G32: 抽出済みエピソード数 | H32: rawファイル数 | I32: 標準偏差のddof | J32: 固定部分＋質問 標準偏差（トークン）
A33: Acrobot-v1 | B33: 1 | C33: 0 | D33: 394 | E33: 394 | F33: 5 | G33: 5 | H33: 5 | I33: 0 | J33: 1.7171172
A34: Acrobot-v1 | B34: 10 | C34: 9 | D34: 349 | E34: 349 | F34: 5 | G34: 5 | H34: 5 | I34: 0 | J34: 1.8034831
A35: MountainCar-v0 | B35: 1 | C35: 0 | D35: 1031 | E35: 1031 | F35: 10 | G35: 10 | H35: 10 | I35: 0 | J35: 1.0750751
A36: MountainCar-v0 | B36: 10 | C36: 9 | D36: 941 | E36: 941 | F36: 10 | G36: 10 | H36: 10 | I36: 0 | J36: 1.1004937
A37: Pendulum-v1 | B37: 1 | C37: 0 | D37: 1990 | E37: 1990 | F37: 10 | G37: 10 | H37: 10 | I37: 0 | J37: 1.0790624
A38: Pendulum-v1 | B38: 10 | C38: 9 | D38: 1900 | E38: 1900 | F38: 10 | G38: 10 | H38: 10 | I38: 0 | J38: 1.0841946
A39: BipedalWalker-v3 | B39: 1 | C39: 0 | D39: n.a. | E39: n.a. | F39: n.a. | G39: n.a. | H39: 2 | I39: 0 | J39: n.a.
A40: BipedalWalker-v3 | B40: 10 | C40: 9 | D40: n.a. | E40: n.a. | F40: n.a. | G40: n.a. | H40: 2 | I40: 0 | J40: n.a.
A41: CartPole-v1 | B41: 1 | C41: 0 | D41: 2495 | E41: 2495 | F41: 5 | G41: 5 | H41: 5 | I41: 0 | J41: 1.3953484
A42: CartPole-v1 | B42: 10 | C42: 9 | D42: 2450 | E42: 2450 | F42: 5 | G42: 5 | H42: 5 | I42: 0 | J42: 1.3814042
A43: FetchPickAndPlace-v2 | B43: 1 | C43: 0 | D43: 490 | E43: 490 | F43: 10 | G43: 10 | H43: 10 | I43: 0 | J43: 7.2467261
A44: FetchPickAndPlace-v2 | B44: 10 | C44: 9 | D44: 400 | E44: 400 | F44: 10 | G44: 10 | H44: 10 | I44: 0 | J44: 1.9407215
A45: FetchPush-v2 | B45: 1 | C45: 0 | D45: 490 | E45: 490 | F45: 10 | G45: 10 | H45: 10 | I45: 0 | J45: 3.9827413
A46: FetchPush-v2 | B46: 10 | C46: 9 | D46: 400 | E46: 400 | F46: 10 | G46: 10 | H46: 10 | I46: 0 | J46: 4.3290812
...

Sheet gpt-5.6-sol
A2: gpt-5.6-sol
A3: Input USD / 1M | B3: =Model_Prices!$C$8 -> 4 | D3: API model | E3: gpt-5.6-sol | G3: Price checked | H3: 2026-09-09
A4: Encoding | B4: o200k_base | D4: tiktoken | E4: 0.14.0 | G4: Seed / max samples | H4: 42 / 10000
A6: H = actual history steps. Upstream H = H-1. Input only; standard uncached rates; +9 framing is an estimate.
A8: タスク | B8: 100回分金額 | C8: H=10 合計金額 平均（USD） | D8: H=10 合計金額 平均＋履歴標準偏差（USD） | E8: 固定部分＋質問 平均トークン数 | F8: H=1 履歴 平均トークン数 | G8: H=1 履歴 標準偏差（トークン） | H8: H=10 履歴 平均トークン数 | I8: H=10 合計 平均トークン数 | J8: H=10 履歴 平均＋標準偏差（トークン） | K8: H=10 合計 平均＋履歴標準偏差（トークン） | L8: H=10 履歴 標準偏差（トークン） | M8: H=10 プロンプト全体 平均トークン数 | N8: H=10 分割集計－全体集計 平均差（トークン） | O8: 計測状況
A9: Acrobot-v1 | B9: =C9*100 -> 0.54160802 | C9: =I9/1000000*Model_Prices!$C$8 -> 0.0054160802 | D9: =K9/1000000*Model_Prices!$C$8 -> 0.0054420578 | E9: 771.27221 | F9: 58.284264 | G9: 1.9924747 | H9: 582.74785 | I9: =E9+H9 -> 1354.0201 | J9: =H9+L9 -> 589.24224 | K9: =E9+J9 -> 1360.5144 | L9: 6.4943905 | M9: 1354.0201 | N9: =ROUND(I9-M9,9) -> 0 | O9: ok
A10: MountainCar-v0 | B10: =C10*100 -> 0.36018789 | C10: =I10/1000000*Model_Prices!$C$8 -> 0.0036018789 | D10: =K10/1000000*Model_Prices!$C$8 -> 0.0036310925 | E10: 579.14346 | F10: 32.086324 | G10: 1.0981499 | H10: 321.32625 | I10: =E10+H10 -> 900.46971 | J10: =H10+L10 -> 328.62967 | K10: =E10+J10 -> 907.77313 | L10: 7.3034167 | M10: 900.46971 | N10: =ROUND(I10-M10,9) -> 0 | O10: ok
A11: Pendulum-v1 | B11: =C11*100 -> 0.58355832 | C11: =I11/1000000*Model_Prices!$C$8 -> 0.0058355832 | D11: =K11/1000000*Model_Prices!$C$8 -> 0.0058543669 | E11: 1014.4711 | F11: 44.422613 | G11: 1.443332 | H11: 444.42474 | I11: =E11+H11 -> 1458.8958 | J11: =H11+L11 -> 449.12066 | K11: =E11+J11 -> 1463.5917 | L11: 4.6959242 | M11: 1458.8958 | N11: =ROUND(I11-M11,9) -> 0 | O11: ok
A12: BipedalWalker-v3 | B12: n.a. | C12: n.a. | D12: n.a. | E12: n.a. | F12: n.a. | G12: n.a. | H12: n.a. | I12: n.a. | J12: n.a. | K12: n.a. | L12: n.a. | M12: n.a. | N12: n.a. | O12: UNSUPPORTED_TASK: Original LLM-X task class/description is unavailable; raw inspection only.
A13: CartPole-v1 | B13: =C13*100 -> 0.47677763 | C13: =I13/1000000*Model_Prices!$C$8 -> 0.0047677763 | D13: =K13/1000000*Model_Prices!$C$8 -> 0.0047893955 | E13: 740.26857 | F13: 45.168337 | G13: 1.4070106 | H13: 451.67551 | I13: =E13+H13 -> 1191.9441 | J13: =H13+L13 -> 457.08031 | K13: =E13+J13 -> 1197.3489 | L13: 5.4047987 | M13: 1191.9441 | N13: =ROUND(I13-M13,9) -> 0 | O13: ok
A14: FetchPickAndPlace-v2 | B14: =C14*100 -> 1.998928 | C14: =I14/1000000*Model_Prices!$C$8 -> 0.01998928 | D14: =K14/1000000*Model_Prices!$C$8 -> 0.020082897 | E14: 2159.06 | F14: 283.51429 | G14: 7.4937253 | H14: 2838.26 | I14: =E14+H14 -> 4997.32 | J14: =H14+L14 -> 2861.6642 | K14: =E14+J14 -> 5020.7242 | L14: 23.404218 | M14: 4997.32 | N14: =ROUND(I14-M14,9) -> 0 | O14: ok
A15: FetchPush-v2 | B15: =C15*100 -> 1.997311 | C15: =I15/1000000*Model_Prices!$C$8 -> 0.01997311 | D15: =K15/1000000*Model_Prices!$C$8 -> 0.020046734 | E15: 2136.1075 | F15: 285.72653 | G15: 4.2420045 | H15: 2857.17 | I15: =E15+H15 -> 4993.2775 | J15: =H15+L15 -> 2875.576 | K15: =E15+J15 -> 5011.6835 | L15: 18.406007 | M15: 4993.2775 | N15: =ROUND(I15-M15,9) -> 0 | O15: ok
A16: FetchSlide-v2 | B16: =C16*100 -> 2.010438 | C16: =I16/1000000*Model_Prices!$C$8 -> 0.02010438 | D16: =K16/1000000*Model_Prices!$C$8 -> 0.020190628 | E16: 2175.5825 | F16: 284.97143 | G16: 6.5211743 | H16: 2850.5125 | I16: =E16+H16 -> 5026.095 | J16: =H16+L16 -> 2872.0744 | K16: =E16+J16 -> 5047.6569 | L16: 21.561884 | M16: 5026.095 | N16: =ROUND(I16-M16,9) -> 0 | O16: ok
A17: HalfCheetah-v4 | B17: n.a. | C17: n.a. | D17: n.a. | E17: n.a. | F17: n.a. | G17: n.a. | H17: n.a. | I17: n.a. | J17: n.a. | K17: n.a. | L17: n.a. | M17: n.a. | N17: n.a. | O17: UNSUPPORTED_TASK: Original LLM-X task class/description is unavailable; raw inspection only.
A18: InvertedDoublePendulum-v4 | B18: =C18*100 -> 0.9267032 | C18: =I18/1000000*Model_Prices!$C$8 -> 0.009267032 | D18: =K18/1000000*Model_Prices!$C$8 -> 0.0093279904 | E18: 1359.3516 | F18: 95.808712 | G18: 4.9012367 | H18: 957.40639 | I18: =E18+H18 -> 2316.758 | J18: =H18+L18 -> 972.64601 | K18: =E18+J18 -> 2331.9976 | L18: 15.239613 | M18: 2316.758 | N18: =ROUND(I18-M18,9) -> 0 | O18: ok
A19: InvertedPendulum-v4 | B19: =C19*100 -> 0.56992748 | C19: =I19/1000000*Model_Prices!$C$8 -> 0.0056992748 | D19: =K19/1000000*Model_Prices!$C$8 -> 0.0057176864 | E19: 939.26178 | F19: 48.595474 | G19: 1.4243317 | H19: 485.55693 | I19: =E19+H19 -> 1424.8187 | J19: =H19+L19 -> 490.15981 | K19: =E19+J19 -> 1429.4216 | L19: 4.6028872 | M19: 1424.8187 | N19: =ROUND(I19-M19,9) -> 0 | O19: ok
A20: LunarLander-v2 | B20: =C20*100 -> 0.68537815 | C20: =I20/1000000*Model_Prices!$C$8 -> 0.0068537815 | D20: =K20/1000000*Model_Prices!$C$8 -> 0.0071585185 | E20: 948.93277 | F20: 76.921727 | G20: 9.110912 | H20: 764.51261 | I20: =E20+H20 -> 1713.4454 | J20: =H20+L20 -> 840.69685 | K20: =E20+J20 -> 1789.6296 | L20: 76.184249 | M20: 1713.4454 | N20: =ROUND(I20-M20,9) -> 0 | O20: ok
A21: MiniGrid-DoorKey-5x5-v0 | B21: n.a. | C21: n.a. | D21: n.a. | E21: n.a. | F21: n.a. | G21: n.a. | H21: n.a. | I21: n.a. | J21: n.a. | K21: n.a. | L21: n.a. | M21: n.a. | N21: n.a. | O21: UNSUPPORTED_TASK: Original LLM-X task class/description is unavailable; raw inspection only.
A22: MiniGrid-Empty-Random-5x5-v0 | B22: n.a. | C22: n.a. | D22: n.a. | E22: n.a. | F22: n.a. | G22: n.a. | H22: n.a. | I22: n.a. | J22: n.a. | K22: n.a. | L22: n.a. | M22: n.a. | N22: n.a. | O22: UNSUPPORTED_TASK: Original LLM-X task class/description is unavailable; raw inspection only.
A23: MiniGrid-Fetch-5x5-N2-v0 | B23: n.a. | C23: n.a. | D23: n.a. | E23: n.a. | F23: n.a. | G23: n.a. | H23: n.a. | I23: n.a. | J23: n.a. | K23: n.a. | L23: n.a. | M23: n.a. | N23: n.a. | O23: UNSUPPORTED_TASK: Original LLM-X task class/description is unavailable; raw inspection only.
A24: MiniGrid-GoToDoor-5x5-v0 | B24: n.a. | C24: n.a. | D24: n.a. | E24: n.a. | F24: n.a. | G24: n.a. | H24: n.a. | I24: n.a. | J24: n.a. | K24: n.a. | L24: n.a. | M24: n.a. | N24: n.a. | O24: UNSUPPORTED_TASK: Original LLM-X task class/description is unavailable; raw inspection only.
A25: MiniGrid-KeyCorridorS3R1-v0 | B25: n.a. | C25: n.a. | D25: n.a. | E25: n.a. | F25: n.a. | G25: n.a. | H25: n.a. | I25: n.a. | J25: n.a. | K25: n.a. | L25: n.a. | M25: n.a. | N25: n.a. | O25: UNSUPPORTED_TASK: Original LLM-X task class/description is unavailable; raw inspection only.
A26: MiniGrid-Unlock-v0 | B26: =C26*100 -> 2.4868 | C26: =I26/1000000*Model_Prices!$C$8 -> 0.024868 | D26: =K26/1000000*Model_Prices!$C$8 -> 0.024868 | E26: 1127 | F26: 509 | G26: 0 | H26: 5090 | I26: =E26+H26 -> 6217 | J26: =H26+L26 -> 5090 | K26: =E26+J26 -> 6217 | L26: 0 | M26: 6217 | N26: =ROUND(I26-M26,9) -> 0 | O26: ok
A27: Pusher-v4 | B27: n.a. | C27: n.a. | D27: n.a. | E27: n.a. | F27: n.a. | G27: n.a. | H27: n.a. | I27: n.a. | J27: n.a. | K27: n.a. | L27: n.a. | M27: n.a. | N27: n.a. | O27: UNSUPPORTED_TASK: Original LLM-X task class/description is unavailable; raw inspection only.
A28: Reacher-v4 | B28: n.a. | C28: n.a. | D28: n.a. | E28: n.a. | F28: n.a. | G28: n.a. | H28: n.a. | I28: n.a. | J28: n.a. | K28: n.a. | L28: n.a. | M28: n.a. | N28: n.a. | O28: UNSUPPORTED_TASK: Original LLM-X task class/description is unavailable; raw inspection only.
A32: タスク | B32: 実際の履歴長H （ステップ） | C32: 公式関数へ渡すH | D32: 有効ウィンドウ数 | E32: 抽出ウィンドウ数 | F32: 抽出対象エピソード数 | G32: 抽出済みエピソード数 | H32: rawファイル数 | I32: 標準偏差のddof | J32: 固定部分＋質問 標準偏差（トークン）
A33: Acrobot-v1 | B33: 1 | C33: 0 | D33: 394 | E33: 394 | F33: 5 | G33: 5 | H33: 5 | I33: 0 | J33: 1.7171172
A34: Acrobot-v1 | B34: 10 | C34: 9 | D34: 349 | E34: 349 | F34: 5 | G34: 5 | H34: 5 | I34: 0 | J34: 1.8034831
A35: MountainCar-v0 | B35: 1 | C35: 0 | D35: 1031 | E35: 1031 | F35: 10 | G35: 10 | H35: 10 | I35: 0 | J35: 1.0750751
A36: MountainCar-v0 | B36: 10 | C36: 9 | D36: 941 | E36: 941 | F36: 10 | G36: 10 | H36: 10 | I36: 0 | J36: 1.1004937
A37: Pendulum-v1 | B37: 1 | C37: 0 | D37: 1990 | E37: 1990 | F37: 10 | G37: 10 | H37: 10 | I37: 0 | J37: 1.0790624
A38: Pendulum-v1 | B38: 10 | C38: 9 | D38: 1900 | E38: 1900 | F38: 10 | G38: 10 | H38: 10 | I38: 0 | J38: 1.0841946
A39: BipedalWalker-v3 | B39: 1 | C39: 0 | D39: n.a. | E39: n.a. | F39: n.a. | G39: n.a. | H39: 2 | I39: 0 | J39: n.a.
A40: BipedalWalker-v3 | B40: 10 | C40: 9 | D40: n.a. | E40: n.a. | F40: n.a. | G40: n.a. | H40: 2 | I40: 0 | J40: n.a.
A41: CartPole-v1 | B41: 1 | C41: 0 | D41: 2495 | E41: 2495 | F41: 5 | G41: 5 | H41: 5 | I41: 0 | J41: 1.3953484
A42: CartPole-v1 | B42: 10 | C42: 9 | D42: 2450 | E42: 2450 | F42: 5 | G42: 5 | H42: 5 | I42: 0 | J42: 1.3814042
A43: FetchPickAndPlace-v2 | B43: 1 | C43: 0 | D43: 490 | E43: 490 | F43: 10 | G43: 10 | H43: 10 | I43: 0 | J43: 7.2467261
A44: FetchPickAndPlace-v2 | B44: 10 | C44: 9 | D44: 400 | E44: 400 | F44: 10 | G44: 10 | H44: 10 | I44: 0 | J44: 1.9407215
A45: FetchPush-v2 | B45: 1 | C45: 0 | D45: 490 | E45: 490 | F45: 10 | G45: 10 | H45: 10 | I45: 0 | J45: 3.9827413
A46: FetchPush-v2 | B46: 10 | C46: 9 | D46: 400 | E46: 400 | F46: 10 | G46: 10 | H46: 10 | I46: 0 | J46: 4.3290812
...

Sheet Sheet1
B1: MountainCar | E1: Pendulum | H1: Fetch系(アーム)
B2: Input | C2: Output | D2: Σ | E2: Input | F2: Output | G2: Σ | H2: Input | I2: Output | J2: Σ
A3: 6-astra | B3: =B4*2.5 -> 0.90046971 | C3: =C4*2.5 -> 4.5023486 | D3: =B3+C3 -> 5.4028183 | E3: =E4*2.5 -> 1.4588958 | F3: =F4*2.5 -> 7.2944789 | G3: =E3+F3 -> 8.7533747 | H3: =H4*2.5 -> 5.0055642 | I3: =I4*2.5 -> 25.027821 | J3: =H3+I3 -> 30.033385
A4: 5.6-sol | B4: ='gpt-5.6-sol'!B10 -> 0.36018789 | C4: =5*B4 -> 1.8009394 | D4: =B4+C4 -> 2.1611273 | E4: ='gpt-5.6-sol'!B11 -> 0.58355832 | F4: =5*E4 -> 2.9177916 | G4: =E4+F4 -> 3.5013499 | H4: =AVERAGE('gpt-5.6-sol'!B14:'gpt-5.6-sol'!B16) -> 2.0022257 | I4: =5*H4 -> 10.011128 | J4: =H4+I4 -> 12.013354
A5: 3.5 | B5: ='chatGPT3.5'!B10 -> 0.045123486 | C5: =5*B5 -> 0.22561743 | D5: =B5+C5 -> 0.27074091 | E5: ='chatGPT3.5'!B11 -> 0.073394789 | F5: =5*E5 -> 0.36697395 | G5: =E5+F5 -> 0.44036874 | H5: =AVERAGE('chatGPT3.5'!B14:'chatGPT3.5'!B16) -> 0.25039487 | I5: =5*H5 -> 1.2519744 | J5: =H5+I5 -> 1.5023692
D8: =D5+D3+G3+G5 -> 14.867303

Sheet gpt-5.6-terra
A2: gpt-5.6-terra
A3: Input USD / 1M | B3: =Model_Prices!$C$9 -> 2 | D3: API model | E3: gpt-5.6-terra | G3: Price checked | H3: 2026-09-09
A4: Encoding | B4: o200k_base | D4: tiktoken | E4: 0.14.0 | G4: Seed / max samples | H4: 42 / 10000
A6: H = actual history steps. Upstream H = H-1. Input only; standard uncached rates; +9 framing is an estimate.
A8: タスク | B8: 100回分金額 | C8: H=10 合計金額 平均（USD） | D8: H=10 合計金額 平均＋履歴標準偏差（USD） | E8: 固定部分＋質問 平均トークン数 | F8: H=1 履歴 平均トークン数 | G8: H=1 履歴 標準偏差（トークン） | H8: H=10 履歴 平均トークン数 | I8: H=10 合計 平均トークン数 | J8: H=10 履歴 平均＋標準偏差（トークン） | K8: H=10 合計 平均＋履歴標準偏差（トークン） | L8: H=10 履歴 標準偏差（トークン） | M8: H=10 プロンプト全体 平均トークン数 | N8: H=10 分割集計－全体集計 平均差（トークン） | O8: 計測状況
A9: Acrobot-v1 | B9: =C9*100 -> 0.27080401 | C9: =I9/1000000*Model_Prices!$C$9 -> 0.0027080401 | D9: =K9/1000000*Model_Prices!$C$9 -> 0.0027210289 | E9: 771.27221 | F9: 58.284264 | G9: 1.9924747 | H9: 582.74785 | I9: =E9+H9 -> 1354.0201 | J9: =H9+L9 -> 589.24224 | K9: =E9+J9 -> 1360.5144 | L9: 6.4943905 | M9: 1354.0201 | N9: =ROUND(I9-M9,9) -> 0 | O9: ok
A10: MountainCar-v0 | B10: =C10*100 -> 0.18009394 | C10: =I10/1000000*Model_Prices!$C$9 -> 0.0018009394 | D10: =K10/1000000*Model_Prices!$C$9 -> 0.0018155463 | E10: 579.14346 | F10: 32.086324 | G10: 1.0981499 | H10: 321.32625 | I10: =E10+H10 -> 900.46971 | J10: =H10+L10 -> 328.62967 | K10: =E10+J10 -> 907.77313 | L10: 7.3034167 | M10: 900.46971 | N10: =ROUND(I10-M10,9) -> 0 | O10: ok
A11: Pendulum-v1 | B11: =C11*100 -> 0.29177916 | C11: =I11/1000000*Model_Prices!$C$9 -> 0.0029177916 | D11: =K11/1000000*Model_Prices!$C$9 -> 0.0029271834 | E11: 1014.4711 | F11: 44.422613 | G11: 1.443332 | H11: 444.42474 | I11: =E11+H11 -> 1458.8958 | J11: =H11+L11 -> 449.12066 | K11: =E11+J11 -> 1463.5917 | L11: 4.6959242 | M11: 1458.8958 | N11: =ROUND(I11-M11,9) -> 0 | O11: ok
A12: BipedalWalker-v3 | B12: n.a. | C12: n.a. | D12: n.a. | E12: n.a. | F12: n.a. | G12: n.a. | H12: n.a. | I12: n.a. | J12: n.a. | K12: n.a. | L12: n.a. | M12: n.a. | N12: n.a. | O12: UNSUPPORTED_TASK: Original LLM-X task class/description is unavailable; raw inspection only.
A13: CartPole-v1 | B13: =C13*100 -> 0.23838882 | C13: =I13/1000000*Model_Prices!$C$9 -> 0.0023838882 | D13: =K13/1000000*Model_Prices!$C$9 -> 0.0023946978 | E13: 740.26857 | F13: 45.168337 | G13: 1.4070106 | H13: 451.67551 | I13: =E13+H13 -> 1191.9441 | J13: =H13+L13 -> 457.08031 | K13: =E13+J13 -> 1197.3489 | L13: 5.4047987 | M13: 1191.9441 | N13: =ROUND(I13-M13,9) -> 0 | O13: ok
A14: FetchPickAndPlace-v2 | B14: =C14*100 -> 0.999464 | C14: =I14/1000000*Model_Prices!$C$9 -> 0.00999464 | D14: =K14/1000000*Model_Prices!$C$9 -> 0.010041448 | E14: 2159.06 | F14: 283.51429 | G14: 7.4937253 | H14: 2838.26 | I14: =E14+H14 -> 4997.32 | J14: =H14+L14 -> 2861.6642 | K14: =E14+J14 -> 5020.7242 | L14: 23.404218 | M14: 4997.32 | N14: =ROUND(I14-M14,9) -> 0 | O14: ok
A15: FetchPush-v2 | B15: =C15*100 -> 0.9986555 | C15: =I15/1000000*Model_Prices!$C$9 -> 0.009986555 | D15: =K15/1000000*Model_Prices!$C$9 -> 0.010023367 | E15: 2136.1075 | F15: 285.72653 | G15: 4.2420045 | H15: 2857.17 | I15: =E15+H15 -> 4993.2775 | J15: =H15+L15 -> 2875.576 | K15: =E15+J15 -> 5011.6835 | L15: 18.406007 | M15: 4993.2775 | N15: =ROUND(I15-M15,9) -> 0 | O15: ok
A16: FetchSlide-v2 | B16: =C16*100 -> 1.005219 | C16: =I16/1000000*Model_Prices!$C$9 -> 0.01005219 | D16: =K16/1000000*Model_Prices!$C$9 -> 0.010095314 | E16: 2175.5825 | F16: 284.97143 | G16: 6.5211743 | H16: 2850.5125 | I16: =E16+H16 -> 5026.095 | J16: =H16+L16 -> 2872.0744 | K16: =E16+J16 -> 5047.6569 | L16: 21.561884 | M16: 5026.095 | N16: =ROUND(I16-M16,9) -> 0 | O16: ok
A17: HalfCheetah-v4 | B17: n.a. | C17: n.a. | D17: n.a. | E17: n.a. | F17: n.a. | G17: n.a. | H17: n.a. | I17: n.a. | J17: n.a. | K17: n.a. | L17: n.a. | M17: n.a. | N17: n.a. | O17: UNSUPPORTED_TASK: Original LLM-X task class/description is unavailable; raw inspection only.
A18: InvertedDoublePendulum-v4 | B18: =C18*100 -> 0.4633516 | C18: =I18/1000000*Model_Prices!$C$9 -> 0.004633516 | D18: =K18/1000000*Model_Prices!$C$9 -> 0.0046639952 | E18: 1359.3516 | F18: 95.808712 | G18: 4.9012367 | H18: 957.40639 | I18: =E18+H18 -> 2316.758 | J18: =H18+L18 -> 972.64601 | K18: =E18+J18 -> 2331.9976 | L18: 15.239613 | M18: 2316.758 | N18: =ROUND(I18-M18,9) -> 0 | O18: ok
A19: InvertedPendulum-v4 | B19: =C19*100 -> 0.28496374 | C19: =I19/1000000*Model_Prices!$C$9 -> 0.0028496374 | D19: =K19/1000000*Model_Prices!$C$9 -> 0.0028588432 | E19: 939.26178 | F19: 48.595474 | G19: 1.4243317 | H19: 485.55693 | I19: =E19+H19 -> 1424.8187 | J19: =H19+L19 -> 490.15981 | K19: =E19+J19 -> 1429.4216 | L19: 4.6028872 | M19: 1424.8187 | N19: =ROUND(I19-M19,9) -> 0 | O19: ok
A20: LunarLander-v2 | B20: =C20*100 -> 0.34268908 | C20: =I20/1000000*Model_Prices!$C$9 -> 0.0034268908 | D20: =K20/1000000*Model_Prices!$C$9 -> 0.0035792593 | E20: 948.93277 | F20: 76.921727 | G20: 9.110912 | H20: 764.51261 | I20: =E20+H20 -> 1713.4454 | J20: =H20+L20 -> 840.69685 | K20: =E20+J20 -> 1789.6296 | L20: 76.184249 | M20: 1713.4454 | N20: =ROUND(I20-M20,9) -> 0 | O20: ok
A21: MiniGrid-DoorKey-5x5-v0 | B21: n.a. | C21: n.a. | D21: n.a. | E21: n.a. | F21: n.a. | G21: n.a. | H21: n.a. | I21: n.a. | J21: n.a. | K21: n.a. | L21: n.a. | M21: n.a. | N21: n.a. | O21: UNSUPPORTED_TASK: Original LLM-X task class/description is unavailable; raw inspection only.
A22: MiniGrid-Empty-Random-5x5-v0 | B22: n.a. | C22: n.a. | D22: n.a. | E22: n.a. | F22: n.a. | G22: n.a. | H22: n.a. | I22: n.a. | J22: n.a. | K22: n.a. | L22: n.a. | M22: n.a. | N22: n.a. | O22: UNSUPPORTED_TASK: Original LLM-X task class/description is unavailable; raw inspection only.
A23: MiniGrid-Fetch-5x5-N2-v0 | B23: n.a. | C23: n.a. | D23: n.a. | E23: n.a. | F23: n.a. | G23: n.a. | H23: n.a. | I23: n.a. | J23: n.a. | K23: n.a. | L23: n.a. | M23: n.a. | N23: n.a. | O23: UNSUPPORTED_TASK: Original LLM-X task class/description is unavailable; raw inspection only.
A24: MiniGrid-GoToDoor-5x5-v0 | B24: n.a. | C24: n.a. | D24: n.a. | E24: n.a. | F24: n.a. | G24: n.a. | H24: n.a. | I24: n.a. | J24: n.a. | K24: n.a. | L24: n.a. | M24: n.a. | N24: n.a. | O24: UNSUPPORTED_TASK: Original LLM-X task class/description is unavailable; raw inspection only.
A25: MiniGrid-KeyCorridorS3R1-v0 | B25: n.a. | C25: n.a. | D25: n.a. | E25: n.a. | F25: n.a. | G25: n.a. | H25: n.a. | I25: n.a. | J25: n.a. | K25: n.a. | L25: n.a. | M25: n.a. | N25: n.a. | O25: UNSUPPORTED_TASK: Original LLM-X task class/description is unavailable; raw inspection only.
A26: MiniGrid-Unlock-v0 | B26: =C26*100 -> 1.2434 | C26: =I26/1000000*Model_Prices!$C$9 -> 0.012434 | D26: =K26/1000000*Model_Prices!$C$9 -> 0.012434 | E26: 1127 | F26: 509 | G26: 0 | H26: 5090 | I26: =E26+H26 -> 6217 | J26: =H26+L26 -> 5090 | K26: =E26+J26 -> 6217 | L26: 0 | M26: 6217 | N26: =ROUND(I26-M26,9) -> 0 | O26: ok
A27: Pusher-v4 | B27: n.a. | C27: n.a. | D27: n.a. | E27: n.a. | F27: n.a. | G27: n.a. | H27: n.a. | I27: n.a. | J27: n.a. | K27: n.a. | L27: n.a. | M27: n.a. | N27: n.a. | O27: UNSUPPORTED_TASK: Original LLM-X task class/description is unavailable; raw inspection only.
A28: Reacher-v4 | B28: n.a. | C28: n.a. | D28: n.a. | E28: n.a. | F28: n.a. | G28: n.a. | H28: n.a. | I28: n.a. | J28: n.a. | K28: n.a. | L28: n.a. | M28: n.a. | N28: n.a. | O28: UNSUPPORTED_TASK: Original LLM-X task class/description is unavailable; raw inspection only.
A32: タスク | B32: 実際の履歴長H （ステップ） | C32: 公式関数へ渡すH | D32: 有効ウィンドウ数 | E32: 抽出ウィンドウ数 | F32: 抽出対象エピソード数 | G32: 抽出済みエピソード数 | H32: rawファイル数 | I32: 標準偏差のddof | J32: 固定部分＋質問 標準偏差（トークン）
A33: Acrobot-v1 | B33: 1 | C33: 0 | D33: 394 | E33: 394 | F33: 5 | G33: 5 | H33: 5 | I33: 0 | J33: 1.7171172
A34: Acrobot-v1 | B34: 10 | C34: 9 | D34: 349 | E34: 349 | F34: 5 | G34: 5 | H34: 5 | I34: 0 | J34: 1.8034831
A35: MountainCar-v0 | B35: 1 | C35: 0 | D35: 1031 | E35: 1031 | F35: 10 | G35: 10 | H35: 10 | I35: 0 | J35: 1.0750751
A36: MountainCar-v0 | B36: 10 | C36: 9 | D36: 941 | E36: 941 | F36: 10 | G36: 10 | H36: 10 | I36: 0 | J36: 1.1004937
A37: Pendulum-v1 | B37: 1 | C37: 0 | D37: 1990 | E37: 1990 | F37: 10 | G37: 10 | H37: 10 | I37: 0 | J37: 1.0790624
A38: Pendulum-v1 | B38: 10 | C38: 9 | D38: 1900 | E38: 1900 | F38: 10 | G38: 10 | H38: 10 | I38: 0 | J38: 1.0841946
A39: BipedalWalker-v3 | B39: 1 | C39: 0 | D39: n.a. | E39: n.a. | F39: n.a. | G39: n.a. | H39: 2 | I39: 0 | J39: n.a.
A40: BipedalWalker-v3 | B40: 10 | C40: 9 | D40: n.a. | E40: n.a. | F40: n.a. | G40: n.a. | H40: 2 | I40: 0 | J40: n.a.
A41: CartPole-v1 | B41: 1 | C41: 0 | D41: 2495 | E41: 2495 | F41: 5 | G41: 5 | H41: 5 | I41: 0 | J41: 1.3953484
A42: CartPole-v1 | B42: 10 | C42: 9 | D42: 2450 | E42: 2450 | F42: 5 | G42: 5 | H42: 5 | I42: 0 | J42: 1.3814042
A43: FetchPickAndPlace-v2 | B43: 1 | C43: 0 | D43: 490 | E43: 490 | F43: 10 | G43: 10 | H43: 10 | I43: 0 | J43: 7.2467261
A44: FetchPickAndPlace-v2 | B44: 10 | C44: 9 | D44: 400 | E44: 400 | F44: 10 | G44: 10 | H44: 10 | I44: 0 | J44: 1.9407215
A45: FetchPush-v2 | B45: 1 | C45: 0 | D45: 490 | E45: 490 | F45: 10 | G45: 10 | H45: 10 | I45: 0 | J45: 3.9827413
A46: FetchPush-v2 | B46: 10 | C46: 9 | D46: 400 | E46: 400 | F46: 10 | G46: 10 | H46: 10 | I46: 0 | J46: 4.3290812
...

Sheet gpt-5.6-luna
A2: gpt-5.6-luna
A3: Input USD / 1M | B3: =Model_Prices!$C$10 -> 0.2 | D3: API model | E3: gpt-5.6-luna | G3: Price checked | H3: 2026-09-09
A4: Encoding | B4: o200k_base | D4: tiktoken | E4: 0.14.0 | G4: Seed / max samples | H4: 42 / 10000
A6: H = actual history steps. Upstream H = H-1. Input only; standard uncached rates; +9 framing is an estimate.
A8: タスク | B8: 100回分金額 | C8: H=10 合計金額 平均（USD） | D8: H=10 合計金額 平均＋履歴標準偏差（USD） | E8: 固定部分＋質問 平均トークン数 | F8: H=1 履歴 平均トークン数 | G8: H=1 履歴 標準偏差（トークン） | H8: H=10 履歴 平均トークン数 | I8: H=10 合計 平均トークン数 | J8: H=10 履歴 平均＋標準偏差（トークン） | K8: H=10 合計 平均＋履歴標準偏差（トークン） | L8: H=10 履歴 標準偏差（トークン） | M8: H=10 プロンプト全体 平均トークン数 | N8: H=10 分割集計－全体集計 平均差（トークン） | O8: 計測状況
A9: Acrobot-v1 | B9: =C9*100 -> 0.027080401 | C9: =I9/1000000*Model_Prices!$C$10 -> 0.00027080401 | D9: =K9/1000000*Model_Prices!$C$10 -> 0.00027210289 | E9: 771.27221 | F9: 58.284264 | G9: 1.9924747 | H9: 582.74785 | I9: =E9+H9 -> 1354.0201 | J9: =H9+L9 -> 589.24224 | K9: =E9+J9 -> 1360.5144 | L9: 6.4943905 | M9: 1354.0201 | N9: =ROUND(I9-M9,9) -> 0 | O9: ok
A10: MountainCar-v0 | B10: =C10*100 -> 0.018009394 | C10: =I10/1000000*Model_Prices!$C$10 -> 0.00018009394 | D10: =K10/1000000*Model_Prices!$C$10 -> 0.00018155463 | E10: 579.14346 | F10: 32.086324 | G10: 1.0981499 | H10: 321.32625 | I10: =E10+H10 -> 900.46971 | J10: =H10+L10 -> 328.62967 | K10: =E10+J10 -> 907.77313 | L10: 7.3034167 | M10: 900.46971 | N10: =ROUND(I10-M10,9) -> 0 | O10: ok
A11: Pendulum-v1 | B11: =C11*100 -> 0.029177916 | C11: =I11/1000000*Model_Prices!$C$10 -> 0.00029177916 | D11: =K11/1000000*Model_Prices!$C$10 -> 0.00029271834 | E11: 1014.4711 | F11: 44.422613 | G11: 1.443332 | H11: 444.42474 | I11: =E11+H11 -> 1458.8958 | J11: =H11+L11 -> 449.12066 | K11: =E11+J11 -> 1463.5917 | L11: 4.6959242 | M11: 1458.8958 | N11: =ROUND(I11-M11,9) -> 0 | O11: ok
A12: BipedalWalker-v3 | B12: n.a. | C12: n.a. | D12: n.a. | E12: n.a. | F12: n.a. | G12: n.a. | H12: n.a. | I12: n.a. | J12: n.a. | K12: n.a. | L12: n.a. | M12: n.a. | N12: n.a. | O12: UNSUPPORTED_TASK: Original LLM-X task class/description is unavailable; raw inspection only.
A13: CartPole-v1 | B13: =C13*100 -> 0.023838882 | C13: =I13/1000000*Model_Prices!$C$10 -> 0.00023838882 | D13: =K13/1000000*Model_Prices!$C$10 -> 0.00023946978 | E13: 740.26857 | F13: 45.168337 | G13: 1.4070106 | H13: 451.67551 | I13: =E13+H13 -> 1191.9441 | J13: =H13+L13 -> 457.08031 | K13: =E13+J13 -> 1197.3489 | L13: 5.4047987 | M13: 1191.9441 | N13: =ROUND(I13-M13,9) -> 0 | O13: ok
A14: FetchPickAndPlace-v2 | B14: =C14*100 -> 0.0999464 | C14: =I14/1000000*Model_Prices!$C$10 -> 0.000999464 | D14: =K14/1000000*Model_Prices!$C$10 -> 0.0010041448 | E14: 2159.06 | F14: 283.51429 | G14: 7.4937253 | H14: 2838.26 | I14: =E14+H14 -> 4997.32 | J14: =H14+L14 -> 2861.6642 | K14: =E14+J14 -> 5020.7242 | L14: 23.404218 | M14: 4997.32 | N14: =ROUND(I14-M14,9) -> 0 | O14: ok
A15: FetchPush-v2 | B15: =C15*100 -> 0.09986555 | C15: =I15/1000000*Model_Prices!$C$10 -> 0.0009986555 | D15: =K15/1000000*Model_Prices!$C$10 -> 0.0010023367 | E15: 2136.1075 | F15: 285.72653 | G15: 4.2420045 | H15: 2857.17 | I15: =E15+H15 -> 4993.2775 | J15: =H15+L15 -> 2875.576 | K15: =E15+J15 -> 5011.6835 | L15: 18.406007 | M15: 4993.2775 | N15: =ROUND(I15-M15,9) -> 0 | O15: ok
A16: FetchSlide-v2 | B16: =C16*100 -> 0.1005219 | C16: =I16/1000000*Model_Prices!$C$10 -> 0.001005219 | D16: =K16/1000000*Model_Prices!$C$10 -> 0.0010095314 | E16: 2175.5825 | F16: 284.97143 | G16: 6.5211743 | H16: 2850.5125 | I16: =E16+H16 -> 5026.095 | J16: =H16+L16 -> 2872.0744 | K16: =E16+J16 -> 5047.6569 | L16: 21.561884 | M16: 5026.095 | N16: =ROUND(I16-M16,9) -> 0 | O16: ok
A17: HalfCheetah-v4 | B17: n.a. | C17: n.a. | D17: n.a. | E17: n.a. | F17: n.a. | G17: n.a. | H17: n.a. | I17: n.a. | J17: n.a. | K17: n.a. | L17: n.a. | M17: n.a. | N17: n.a. | O17: UNSUPPORTED_TASK: Original LLM-X task class/description is unavailable; raw inspection only.
A18: InvertedDoublePendulum-v4 | B18: =C18*100 -> 0.04633516 | C18: =I18/1000000*Model_Prices!$C$10 -> 0.0004633516 | D18: =K18/1000000*Model_Prices!$C$10 -> 0.00046639952 | E18: 1359.3516 | F18: 95.808712 | G18: 4.9012367 | H18: 957.40639 | I18: =E18+H18 -> 2316.758 | J18: =H18+L18 -> 972.64601 | K18: =E18+J18 -> 2331.9976 | L18: 15.239613 | M18: 2316.758 | N18: =ROUND(I18-M18,9) -> 0 | O18: ok
A19: InvertedPendulum-v4 | B19: =C19*100 -> 0.028496374 | C19: =I19/1000000*Model_Prices!$C$10 -> 0.00028496374 | D19: =K19/1000000*Model_Prices!$C$10 -> 0.00028588432 | E19: 939.26178 | F19: 48.595474 | G19: 1.4243317 | H19: 485.55693 | I19: =E19+H19 -> 1424.8187 | J19: =H19+L19 -> 490.15981 | K19: =E19+J19 -> 1429.4216 | L19: 4.6028872 | M19: 1424.8187 | N19: =ROUND(I19-M19,9) -> 0 | O19: ok
A20: LunarLander-v2 | B20: =C20*100 -> 0.034268908 | C20: =I20/1000000*Model_Prices!$C$10 -> 0.00034268908 | D20: =K20/1000000*Model_Prices!$C$10 -> 0.00035792593 | E20: 948.93277 | F20: 76.921727 | G20: 9.110912 | H20: 764.51261 | I20: =E20+H20 -> 1713.4454 | J20: =H20+L20 -> 840.69685 | K20: =E20+J20 -> 1789.6296 | L20: 76.184249 | M20: 1713.4454 | N20: =ROUND(I20-M20,9) -> 0 | O20: ok
A21: MiniGrid-DoorKey-5x5-v0 | B21: n.a. | C21: n.a. | D21: n.a. | E21: n.a. | F21: n.a. | G21: n.a. | H21: n.a. | I21: n.a. | J21: n.a. | K21: n.a. | L21: n.a. | M21: n.a. | N21: n.a. | O21: UNSUPPORTED_TASK: Original LLM-X task class/description is unavailable; raw inspection only.
A22: MiniGrid-Empty-Random-5x5-v0 | B22: n.a. | C22: n.a. | D22: n.a. | E22: n.a. | F22: n.a. | G22: n.a. | H22: n.a. | I22: n.a. | J22: n.a. | K22: n.a. | L22: n.a. | M22: n.a. | N22: n.a. | O22: UNSUPPORTED_TASK: Original LLM-X task class/description is unavailable; raw inspection only.
A23: MiniGrid-Fetch-5x5-N2-v0 | B23: n.a. | C23: n.a. | D23: n.a. | E23: n.a. | F23: n.a. | G23: n.a. | H23: n.a. | I23: n.a. | J23: n.a. | K23: n.a. | L23: n.a. | M23: n.a. | N23: n.a. | O23: UNSUPPORTED_TASK: Original LLM-X task class/description is unavailable; raw inspection only.
A24: MiniGrid-GoToDoor-5x5-v0 | B24: n.a. | C24: n.a. | D24: n.a. | E24: n.a. | F24: n.a. | G24: n.a. | H24: n.a. | I24: n.a. | J24: n.a. | K24: n.a. | L24: n.a. | M24: n.a. | N24: n.a. | O24: UNSUPPORTED_TASK: Original LLM-X task class/description is unavailable; raw inspection only.
A25: MiniGrid-KeyCorridorS3R1-v0 | B25: n.a. | C25: n.a. | D25: n.a. | E25: n.a. | F25: n.a. | G25: n.a. | H25: n.a. | I25: n.a. | J25: n.a. | K25: n.a. | L25: n.a. | M25: n.a. | N25: n.a. | O25: UNSUPPORTED_TASK: Original LLM-X task class/description is unavailable; raw inspection only.
A26: MiniGrid-Unlock-v0 | B26: =C26*100 -> 0.12434 | C26: =I26/1000000*Model_Prices!$C$10 -> 0.0012434 | D26: =K26/1000000*Model_Prices!$C$10 -> 0.0012434 | E26: 1127 | F26: 509 | G26: 0 | H26: 5090 | I26: =E26+H26 -> 6217 | J26: =H26+L26 -> 5090 | K26: =E26+J26 -> 6217 | L26: 0 | M26: 6217 | N26: =ROUND(I26-M26,9) -> 0 | O26: ok
A27: Pusher-v4 | B27: n.a. | C27: n.a. | D27: n.a. | E27: n.a. | F27: n.a. | G27: n.a. | H27: n.a. | I27: n.a. | J27: n.a. | K27: n.a. | L27: n.a. | M27: n.a. | N27: n.a. | O27: UNSUPPORTED_TASK: Original LLM-X task class/description is unavailable; raw inspection only.
A28: Reacher-v4 | B28: n.a. | C28: n.a. | D28: n.a. | E28: n.a. | F28: n.a. | G28: n.a. | H28: n.a. | I28: n.a. | J28: n.a. | K28: n.a. | L28: n.a. | M28: n.a. | N28: n.a. | O28: UNSUPPORTED_TASK: Original LLM-X task class/description is unavailable; raw inspection only.
A32: タスク | B32: 実際の履歴長H （ステップ） | C32: 公式関数へ渡すH | D32: 有効ウィンドウ数 | E32: 抽出ウィンドウ数 | F32: 抽出対象エピソード数 | G32: 抽出済みエピソード数 | H32: rawファイル数 | I32: 標準偏差のddof | J32: 固定部分＋質問 標準偏差（トークン）
A33: Acrobot-v1 | B33: 1 | C33: 0 | D33: 394 | E33: 394 | F33: 5 | G33: 5 | H33: 5 | I33: 0 | J33: 1.7171172
A34: Acrobot-v1 | B34: 10 | C34: 9 | D34: 349 | E34: 349 | F34: 5 | G34: 5 | H34: 5 | I34: 0 | J34: 1.8034831
A35: MountainCar-v0 | B35: 1 | C35: 0 | D35: 1031 | E35: 1031 | F35: 10 | G35: 10 | H35: 10 | I35: 0 | J35: 1.0750751
A36: MountainCar-v0 | B36: 10 | C36: 9 | D36: 941 | E36: 941 | F36: 10 | G36: 10 | H36: 10 | I36: 0 | J36: 1.1004937
A37: Pendulum-v1 | B37: 1 | C37: 0 | D37: 1990 | E37: 1990 | F37: 10 | G37: 10 | H37: 10 | I37: 0 | J37: 1.0790624
A38: Pendulum-v1 | B38: 10 | C38: 9 | D38: 1900 | E38: 1900 | F38: 10 | G38: 10 | H38: 10 | I38: 0 | J38: 1.0841946
A39: BipedalWalker-v3 | B39: 1 | C39: 0 | D39: n.a. | E39: n.a. | F39: n.a. | G39: n.a. | H39: 2 | I39: 0 | J39: n.a.
A40: BipedalWalker-v3 | B40: 10 | C40: 9 | D40: n.a. | E40: n.a. | F40: n.a. | G40: n.a. | H40: 2 | I40: 0 | J40: n.a.
A41: CartPole-v1 | B41: 1 | C41: 0 | D41: 2495 | E41: 2495 | F41: 5 | G41: 5 | H41: 5 | I41: 0 | J41: 1.3953484
A42: CartPole-v1 | B42: 10 | C42: 9 | D42: 2450 | E42: 2450 | F42: 5 | G42: 5 | H42: 5 | I42: 0 | J42: 1.3814042
A43: FetchPickAndPlace-v2 | B43: 1 | C43: 0 | D43: 490 | E43: 490 | F43: 10 | G43: 10 | H43: 10 | I43: 0 | J43: 7.2467261
A44: FetchPickAndPlace-v2 | B44: 10 | C44: 9 | D44: 400 | E44: 400 | F44: 10 | G44: 10 | H44: 10 | I44: 0 | J44: 1.9407215
A45: FetchPush-v2 | B45: 1 | C45: 0 | D45: 490 | E45: 490 | F45: 10 | G45: 10 | H45: 10 | I45: 0 | J45: 3.9827413
A46: FetchPush-v2 | B46: 10 | C46: 9 | D46: 400 | E46: 400 | F46: 10 | G46: 10 | H46: 10 | I46: 0 | J46: 4.3290812
...

Sheet Model_Prices
A2: Model prices (USD / 1M tokens)
A3: Edit yellow price cells. Cost columns use Input only; token statistics do not change.
A5: モデル | B5: APIモデルID | C5: 入力単価 | D5: キャッシュ入力単価 | E5: キャッシュ書込単価 | F5: 出力単価 | G5: 確認日 | I5: 公式情報の参照先
A6: chatGPT3.5 | B6: gpt-3.5-turbo | C6: 0.5 | D6: n.a. | E6: n.a. | F6: 1.5 | G6: 2026-09-09 | I6: https://developers.openai.com/api/docs/models/gpt-3.5-turbo
A7: gpt-6-astra | B7: gpt-6-astra | C7: 10 | D7: 1 | E7: 12.5 | F7: 50 | G7: 2026-09-09 | I7: https://developers.openai.com/api/docs/models/gpt-6-astra
A8: gpt-5.6-sol | B8: gpt-5.6-sol | C8: 4 | D8: 0.4 | E8: 5 | F8: 20 | G8: 2026-09-09 | I8: https://developers.openai.com/api/docs/models/gpt-5.6-sol
A9: gpt-5.6-terra | B9: gpt-5.6-terra | C9: 2 | D9: 0.2 | E9: 2.5 | F9: 12 | G9: 2026-09-09 | I9: https://developers.openai.com/api/docs/models/gpt-5.6-terra
A10: gpt-5.6-luna | B10: gpt-5.6-luna | C10: 0.2 | D10: 0.02 | E10: 0.25 | F10: 1.2 | G10: 2026-09-09 | I10: https://developers.openai.com/api/docs/models/gpt-5.6-luna
A12: Standard rates. GPT-5.6/GPT-6 rows apply to requests up to 272K input tokens. No Batch/Flex/Fast adjustments.
A13: Cache write = published 1.25x Input rate for GPT-5.6/GPT-6. GPT-3.5 cache rates are not listed (n.a.), not zero.
A14: Astra price is retained for reference; its estimate sheet is omitted at user request.
A15: Keep model rows in place; formulas use direct row references. Rerunning the script restores the prices in MODELS.

Sheet task description
A2: Task description: official raw episodes
A3: All available episodes, not sampled windows. Raw dimensions are before preprocessing.
A5: タスク | B5: データセット | C5: エピソード数 | D5: 総タイムステップ数 | E5: 平均エピソード長 （ステップ） | F5: 最小エピソード長 （ステップ） | G5: 最大エピソード長 （ステップ） | H5: 状態の次元数 | I5: 行動の次元数 | J5: 報酬の次元数
A6: Acrobot-v1 | B6: physics_data | C6: 5 | D6: 399 | E6: 79.8 | F6: 69 | G6: 90 | H6: 6 | I6: 1 | J6: 1
A7: MountainCar-v0 | B7: physics_data | C7: 10 | D7: 1041 | E7: 104.1 | F7: 88 | G7: 112 | H7: 2 | I7: 1 | J7: 1
A8: Pendulum-v1 | B8: physics_data | C8: 10 | D8: 2000 | E8: 200 | F8: 200 | G8: 200 | H8: 3 | I8: 1 | J8: 1
A9: BipedalWalker-v3 | B9: physics_data | C9: 2 | D9: 144 | E9: 72 | F9: 70 | G9: 74 | H9: 24 | I9: 4 | J9: 1
A10: CartPole-v1 | B10: physics_data | C10: 5 | D10: 2500 | E10: 500 | F10: 500 | G10: 500 | H10: 4 | I10: 1 | J10: 1
A11: FetchPickAndPlace-v2 | B11: robotics_data | C11: 10 | D11: 500 | E11: 50 | F11: 50 | G11: 50 | H11: 26 | I11: 4 | J11: 1
A12: FetchPush-v2 | B12: robotics_data | C12: 10 | D12: 500 | E12: 50 | F12: 50 | G12: 50 | H12: 26 | I12: 4 | J12: 1
A13: FetchSlide-v2 | B13: robotics_data | C13: 10 | D13: 500 | E13: 50 | F13: 50 | G13: 50 | H13: 26 | I13: 4 | J13: 1
A14: HalfCheetah-v4 | B14: mujoco_data | C14: 3 | D14: 3000 | E14: 1000 | F14: 1000 | G14: 1000 | H14: 17 | I14: 6 | J14: 1
A15: InvertedDoublePendulum-v4 | B15: physics_data | C15: 10 | D15: 538 | E15: 53.8 | F15: 31 | G15: 135 | H15: 11 | I15: 1 | J15: 1
A16: InvertedPendulum-v4 | B16: physics_data | C16: 5 | D16: 1419 | E16: 283.8 | F16: 5 | G16: 1000 | H16: 4 | I16: 1 | J16: 1
A17: LunarLander-v2 | B17: physics_data | C17: 3 | D17: 744 | E17: 248 | F17: 246 | G17: 252 | H17: 8 | I17: 1 | J17: 1
... A25: Reacher-v4 | B25: mujoco_data | C25: 5 | D25: 250 | E25: 50 | F25: 50 | G25: 50 | H25: 11 | I25: 2 | J25: 1
A29: タスク | B29: 状態配列の形状 | C29: 行動配列の形状 | D29: 報酬配列の形状 | E29: 状態のデータ型 | F29: 行動のデータ型 | G29: 報酬のデータ型 | H29: NPZ内の配列キー | I29: エピソードファイル 合計容量（バイト） | J29: 時間軸を除く スキーマの一致 | K29: 行動の種別 （観測値から推定）
A30: Acrobot-v1 | B30: ('T', 1, 6) | C30: ('T', 1) | D30: ('T', 1) | E30: float32 | F30: int64 | G30: float64 | H30: actions, episodic_return, rewards, states | I30: 21080 | J30: TRUE | K30: discrete
A31: MountainCar-v0 | B31: ('T', 1, 2) | C31: ('T', 1) | D31: ('T', 1) | E31: float32 | F31: int64 | G31: float64 | H31: actions, episodic_return, rewards, states | I31: 35224 | J31: TRUE | K31: discrete
A32: Pendulum-v1 | B32: ('T', 1, 3) | C32: ('T', 1, 1) | D32: ('T', 1) | E32: float32 | F32: float32 | G32: float64 | H32: actions, episodic_return, rewards, states | I32: 58240 | J32: TRUE | K32: continuous
A33: BipedalWalker-v3 | B33: ('T', 1, 24) | C33: ('T', 1, 4) | D33: ('T', 1) | E33: float32 | F33: float32 | G33: float64 | H33: actions, episodic_return, rewards, states | I33: 19328 | J33: TRUE | K33: continuous
A34: CartPole-v1 | B34: ('T', 1, 4) | C34: ('T', 1) | D34: ('T', 1) | E34: float32 | F34: int64 | G34: float64 | H34: actions, episodic_return, rewards, states | I34: 85120 | J34: TRUE | K34: discrete
A35: FetchPickAndPlace-v2 | B35: ('T', 1, 26) | C35: ('T', 1, 4) | D35: ('T', 1) | E35: float64 | F35: float32 | G35: float32 | H35: achieved_goals, actions, desired_goals, episodic_return, rewards, states | I35: 153460 | J35: TRUE | K35: continuous
A36: FetchPush-v2 | B36: ('T', 1, 26) | C36: ('T', 1, 4) | D36: ('T', 1) | E36: float64 | F36: float32 | G36: float32 | H36: achieved_goals, actions, desired_goals, episodic_return, rewards, states | I36: 153460 | J36: TRUE | K36: continuous
A37: FetchSlide-v2 | B37: ('T', 1, 26) | C37: ('T', 1, 4) | D37: ('T', 1) | E37: float64 | F37: float32 | G37: float32 | H37: achieved_goals, actions, desired_goals, episodic_return, rewards, states | I37: 153460 | J37: TRUE | K37: continuous
A38: HalfCheetah-v4 | B38: ('T', 1, 17) | C38: ('T', 1, 6) | D38: ('T', 1) | E38: float64 | F38: float32 | G38: float64 | H38: actions, episodic_return, rewards, states | I38: 507072 | J38: TRUE | K38: continuous
A39: InvertedDoublePendulum-v4 | B39: ('T', 1, 11) | C39: ('T', 1, 1) | D39: ('T', 1) | E39: float64 | F39: float32 | G39: float64 | H39: actions, episodic_return, rewards, states | I39: 64040 | J39: TRUE | K39: continuous
A40: InvertedPendulum-v4 | B40: ('T', 1, 4) | C40: ('T', 1, 1) | D40: ('T', 1) | E40: float64 | F40: float32 | G40: float64 | H40: actions, episodic_return, rewards, states | I40: 67556 | J40: TRUE | K40: continuous
A41: LunarLander-v2 | B41: ('T', 1, 8) | C41: ('T', 1) | D41: ('T', 1) | E41: float32 | F41: int64 | G41: float64 | H41: actions, episodic_return, rewards, states | I41: 38784 | J41: TRUE | K41: discrete
... A49: Reacher-v4 | B49: ('T', 1, 11) | C49: ('T', 1, 2) | D49: ('T', 1) | E49: float64 | F49: float32 | G49: float64 | H49: actions, episodic_return, rewards, states | I49: 31120 | J49: TRUE | K49: continuous
A52: Source: tools.inventory_llmx_data.create_inventory -> tools.live_inspection.official_frames, as in notebooks/01_data_and_token_inspection.ipynb.
A53: Raw files: data/llmx_data/offline_data/<dataset>/raw_transitions/<task>/episodes/*.npz. One file = one episode.
A54: Episode length = states.shape[0]. Total = sum of lengths. Mean = arithmetic mean across episodes; min/max use the same population.
A55: Dimensions = product of shape[1:] (all non-time axes), not ndarray.ndim. Discrete action dimension 1 is not the number of possible actions.
A56: T denotes the episode time axis. Singleton axes are retained. All observed shape/dtype variants are listed; multiple dimensions appear as a list.
A57: Raw dimensions differ from processed input selection (e.g. Fetch feature selection). No raw arrays are modified.
A58: action_kind_observed is the inventory heuristic: a scalar integer-valued action is labelled discrete. This is not verified environment action-space metadata.
A59: raw_episode_files_size_bytes is NPZ container size. schema_consistent_except_T checks every NPZ key/shape/dtype with the time length abstracted as T.
